Workbook

Sheet Norms & Assumptions
A1: PINE FELLING PRODUCTION PLAN – NORMS & ASSUMPTIONS
A2: Nkomati Mine, Mpumalanga, South Africa | Equipment: Stihl MS 382 | Mon–Fri 07:00–15:30
A4: SECTION 1 – PROJECT SCHEDULE & STAFFING
A5: Parameter | B5: Value | C5: Unit | D5: Notes
A6: Project Start Date | B6: 46111 | C6: date | D6: First working day on site
A7: Phase 2 Start (4 operators) | B7: 46120 | C7: date | D7: 2 additional operators join
A8: Operators – Phase 1 (30 Mar – 07 Apr) | B8: 2 | C8: operators | D8: 2 chainsaw operators
A9: Operators – Phase 2 (08 Apr onwards) | B9: 4 | C9: operators | D9: 4 chainsaw operators total
A10: Shift start | B10: 07:00 | C10: hh:mm | D10: 07:00 daily
A11: Shift end | B11: 15:30 | C11: hh:mm | D11: 15:30 daily
A12: Working hours per shift | B12: 8.5 | C12: hrs | D12: 07:00–15:30 gross
A13: Effective cutting hours | B13: 6.5 | C13: hrs | D13: Excl. travel, fueling, sharpening, breaks
A14: Working days | B14: Mon–Fri | D14: Excluding SA public holidays
A16: SECTION 2 – 2026 SA PUBLIC HOLIDAYS (Days NOT worked)
A17: Date | B17: Holiday | C17: Day | D17: Impact on Schedule
A18: 46023 | B18: New Year's Day | C18: Thursday | D18: Before project start
A19: 46102 | B19: Human Rights Day | C19: Saturday | D19: Before project start
A20: 46115 | B20: Good Friday | C20: Friday | D20: ⚠ Project day lost – no production
A21: 46118 | B21: Family Day (Easter Monday) | C21: Monday | D21: ⚠ Project day lost – no production
A22: 46139 | B22: Freedom Day | C22: Monday | D22: ⚠ Project day lost – no production
A23: 46143 | B23: Workers' Day | C23: Friday | D23: ⚠ Project day lost – no production
A24: 46189 | B24: Youth Day | C24: Tuesday | D24: ⚠ Project day lost – no production
A25: 46243 | B25: National Women's Day | C25: Sunday | D25: ⚠ Project day lost – no production
A26: 46289 | B26: Heritage Day | C26: Thursday | D26: ⚠ Project day lost – no production
A27: 46372 | B27: Day of Reconciliation | C27: Wednesday | D27: ⚠ Project day lost – no production
A28: 46381 | B28: Christmas Day | C28: Friday | D28: ⚠ Project day lost – no production
A29: 46382 | B29: Day of Goodwill | C29: Saturday | D29: ⚠ Project day lost – no production
A31: SECTION 3 – SA CHAINSAW FELLING NORMS (Stihl MS 382)
A32: Parameter | B32: Value | C32: Unit | D32: Source / Notes
A33: Trees felled per operator per day | B33: 150 | C33: trees/day | D33: SA Forestry norm – clear-fell pine, flat-moderate terrain
A34: Avg tree volume – mature pine >15yr | B34: 0.35 | C34: m³/tree | D34: FSA guideline, Mpumalanga pine 25–35cm DBH
A35: Avg tree volume – young pine <15yr | B35: 0.18 | C35: m³/tree | D35: FSA guideline, smaller diameter stands
A36: Target m³ per operator per day | B36: 52.5 | C36: m³/day | D36: 150 trees x 0.35 m3 (mature pine)
A37: Average trees per hectare | B37: 800 | C37: trees/ha | D37: Plantation norm; adjust per compartment
A38: Terrain adjustment – hilly/sloped | B38: 0.85 | C38: factor | D38: 15% reduction for difficult terrain
A41: SECTION 4 – CONSUMABLES NORMS (per operator per day, Stihl MS 382)
A42: Parameter | B42: Value | C42: Unit | D42: Notes
A43: 2-stroke fuel mix (50:1) | B43: 2.5 | C43: litres/day | D43: Petrol + 2T oil mixed 50:1
A44: Bar & chain oil | B44: 1.2 | C44: litres/day | D44: Automatic oiler consumption
A45: Saw chains (replacements) | B45: 0.5 | C45: chains/day | D45: ~1 chain per 2 days hard cutting
...

Sheet Project Schedule
A1: PROJECT SCHEDULE – DAY-BY-DAY PRODUCTION CALENDAR
A2: Start: 30 Mar 2026 | Phase 1: 2 operators | Phase 2 from 08 Apr: 4 operators | Mon–Fri 07:00–15:30 | SA Holidays excluded
A3: PHASE 1 (30 Mar – 07 Apr 2026) – 2 Operators | G3: PHASE 2 (08 Apr 2026 onwards) – 4 Operators
A4: Day | B4: Date | C4: Day of Week | D4: Status | E4: Operators Working | F4: Target Trees/Day | G4: Target m³/Day | H4: Actual Trees | I4: Actual m³ | J4: Tree Variance | K4: m³ Variance | L4: Achievement % | M4: Notes
A5: 1 | B5: 46111 | C5: Monday | D5: Phase 1 – Working Day 1 | E5: 2 | F5: ='Norms & Assumptions'!B33*E5 -> 300 | G5: ='Norms & Assumptions'!B35*E5 -> 0.36 | J5: =IF(H5="","",H5-F5) | K5: =IF(I5="","",I5-G5) | L5: =IF(OR(H5="",F5=0),"",H5/F5)
A6: 2 | B6: 46112 | C6: Tuesday | D6: Phase 1 – Working Day 2 | E6: 2 | F6: ='Norms & Assumptions'!B33*E6 -> 300 | G6: ='Norms & Assumptions'!B35*E6 -> 0.36 | J6: =IF(H6="","",H6-F6) | K6: =IF(I6="","",I6-G6) | L6: =IF(OR(H6="",F6=0),"",H6/F6)
A7: 3 | B7: 46113 | C7: Wednesday | D7: Phase 1 – Working Day 3 | E7: 2 | F7: ='Norms & Assumptions'!B33*E7 -> 300 | G7: ='Norms & Assumptions'!B35*E7 -> 0.36 | J7: =IF(H7="","",H7-F7) | K7: =IF(I7="","",I7-G7) | L7: =IF(OR(H7="",F7=0),"",H7/F7)
A8: 4 | B8: 46114 | C8: Thursday | D8: Phase 1 – Working Day 4 | E8: 2 | F8: ='Norms & Assumptions'!B33*E8 -> 300 | G8: ='Norms & Assumptions'!B35*E8 -> 0.36 | J8: =IF(H8="","",H8-F8) | K8: =IF(I8="","",I8-G8) | L8: =IF(OR(H8="",F8=0),"",H8/F8)
B9: 46115 | C9: Friday | D9: 🏖 Good Friday | E9: 0 | F9: 0 | G9: 0
B10: 46116 | C10: Saturday | D10: Weekend | E10: 0 | F10: 0 | G10: 0
B11: 46117 | C11: Sunday | D11: Weekend | E11: 0 | F11: 0 | G11: 0
B12: 46118 | C12: Monday | D12: 🏖 Family Day (Easter Monday) | E12: 0 | F12: 0 | G12: 0
A13: 5 | B13: 46119 | C13: Tuesday | D13: Phase 1 – Working Day 5 | E13: 2 | F13: ='Norms & Assumptions'!B33*E13 -> 300 | G13: ='Norms & Assumptions'!B35*E13 -> 0.36 | J13: =IF(H13="","",H13-F13) | K13: =IF(I13="","",I13-G13) | L13: =IF(OR(H13="",F13=0),"",H13/F13)
A14: 6 | B14: 46120 | C14: Wednesday | D14: Phase 2 – Working Day 6 | E14: 4 | F14: ='Norms & Assumptions'!B33*E14 -> 600 | G14: ='Norms & Assumptions'!B35*E14 -> 0.72 | J14: =IF(H14="","",H14-F14) | K14: =IF(I14="","",I14-G14) | L14: =IF(OR(H14="",F14=0),"",H14/F14)
A15: 7 | B15: 46121 | C15: Thursday | D15: Phase 2 – Working Day 7 | E15: 4 | F15: ='Norms & Assumptions'!B33*E15 -> 600 | G15: ='Norms & Assumptions'!B35*E15 -> 0.72 | J15: =IF(H15="","",H15-F15) | K15: =IF(I15="","",I15-G15) | L15: =IF(OR(H15="",F15=0),"",H15/F15)
A16: 8 | B16: 46122 | C16: Friday | D16: Phase 2 – Working Day 8 | E16: 4 | F16: ='Norms & Assumptions'!B33*E16 -> 600 | G16: ='Norms & Assumptions'!B35*E16 -> 0.72 | J16: =IF(H16="","",H16-F16) | K16: =IF(I16="","",I16-G16) | L16: =IF(OR(H16="",F16=0),"",H16/F16)
B17: 46123 | C17: Saturday | D17: Weekend | E17: 0 | F17: 0 | G17: 0
B18: 46124 | C18: Sunday | D18: Weekend | E18: 0 | F18: 0 | G18: 0
A19: 9 | B19: 46125 | C19: Monday | D19: Phase 2 – Working Day 9 | E19: 4 | F19: ='Norms & Assumptions'!B33*E19 -> 600 | G19: ='Norms & Assumptions'!B35*E19 -> 0.72 | J19: =IF(H19="","",H19-F19) | K19: =IF(I19="","",I19-G19) | L19: =IF(OR(H19="",F19=0),"",H19/F19)
A20: 10 | B20: 46126 | C20: Tuesday | D20: Phase 2 – Working Day 10 | E20: 4 | F20: ='Norms & Assumptions'!B33*E20 -> 600 | G20: ='Norms & Assumptions'!B35*E20 -> 0.72 | J20: =IF(H20="","",H20-F20) | K20: =IF(I20="","",I20-G20) | L20: =IF(OR(H20="",F20=0),"",H20/F20)
A21: 11 | B21: 46127 | C21: Wednesday | D21: Phase 2 – Working Day 11 | E21: 4 | F21: ='Norms & Assumptions'!B33*E21 -> 600 | G21: ='Norms & Assumptions'!B35*E21 -> 0.72 | J21: =IF(H21="","",H21-F21) | K21: =IF(I21="","",I21-G21) | L21: =IF(OR(H21="",F21=0),"",H21/F21)
A22: 12 | B22: 46128 | C22: Thursday | D22: Phase 2 – Working Day 12 | E22: 4 | F22: ='Norms & Assumptions'!B33*E22 -> 600 | G22: ='Norms & Assumptions'!B35*E22 -> 0.72 | J22: =IF(H22="","",H22-F22) | K22: =IF(I22="","",I22-G22) | L22: =IF(OR(H22="",F22=0),"",H22/F22)
A23: 13 | B23: 46129 | C23: Friday | D23: Phase 2 – Working Day 13 | E23: 4 | F23: ='Norms & Assumptions'!B33*E23 -> 600 | G23: ='Norms & Assumptions'!B35*E23 -> 0.72 | J23: =IF(H23="","",H23-F23) | K23: =IF(I23="","",I23-G23) | L23: =IF(OR(H23="",F23=0),"",H23/F23)
B24: 46130 | C24: Saturday | D24: Weekend | E24: 0 | F24: 0 | G24: 0
B25: 46131 | C25: Sunday | D25: Weekend | E25: 0 | F25: 0 | G25: 0
A26: 14 | B26: 46132 | C26: Monday | D26: Phase 2 – Working Day 14 | E26: 4 | F26: ='Norms & Assumptions'!B33*E26 -> 600 | G26: ='Norms & Assumptions'!B35*E26 -> 0.72 | J26: =IF(H26="","",H26-F26) | K26: =IF(I26="","",I26-G26) | L26: =IF(OR(H26="",F26=0),"",H26/F26)
A27: 15 | B27: 46133 | C27: Tuesday | D27: Phase 2 – Working Day 15 | E27: 4 | F27: ='Norms & Assumptions'!B33*E27 -> 600 | G27: ='Norms & Assumptions'!B35*E27 -> 0.72 | J27: =IF(H27="","",H27-F27) | K27: =IF(I27="","",I27-G27) | L27: =IF(OR(H27="",F27=0),"",H27/F27)
A28: 16 | B28: 46134 | C28: Wednesday | D28: Phase 2 – Working Day 16 | E28: 4 | F28: ='Norms & Assumptions'!B33*E28 -> 600 | G28: ='Norms & Assumptions'!B35*E28 -> 0.72 | J28: =IF(H28="","",H28-F28) | K28: =IF(I28="","",I28-G28) | L28: =IF(OR(H28="",F28=0),"",H28/F28)
A29: 17 | B29: 46135 | C29: Thursday | D29: Phase 2 – Working Day 17 | E29: 4 | F29: ='Norms & Assumptions'!B33*E29 -> 600 | G29: ='Norms & Assumptions'!B35*E29 -> 0.72 | J29: =IF(H29="","",H29-F29) | K29: =IF(I29="","",I29-G29) | L29: =IF(OR(H29="",F29=0),"",H29/F29)
A30: 18 | B30: 46136 | C30: Friday | D30: Phase 2 – Working Day 18 | E30: 4 | F30: ='Norms & Assumptions'!B33*E30 -> 600 | G30: ='Norms & Assumptions'!B35*E30 -> 0.72 | J30: =IF(H30="","",H30-F30) | K30: =IF(I30="","",I30-G30) | L30: =IF(OR(H30="",F30=0),"",H30/F30)
B31: 46137 | C31: Saturday | D31: Weekend | E31: 0 | F31: 0 | G31: 0
B32: 46138 | C32: Sunday | D32: Weekend | E32: 0 | F32: 0 | G32: 0
B33: 46139 | C33: Monday | D33: 🏖 Freedom Day | E33: 0 | F33: 0 | G33: 0
A34: 19 | B34: 46140 | C34: Tuesday | D34: Phase 2 – Working Day 19 | E34: 4 | F34: ='Norms & Assumptions'!B33*E34 -> 600 | G34: ='Norms & Assumptions'!B35*E34 -> 0.72 | J34: =IF(H34="","",H34-F34) | K34: =IF(I34="","",I34-G34) | L34: =IF(OR(H34="",F34=0),"",H34/F34)
A35: 20 | B35: 46141 | C35: Wednesday | D35: Phase 2 – Working Day 20 | E35: 4 | F35: ='Norms & Assumptions'!B33*E35 -> 600 | G35: ='Norms & Assumptions'!B35*E35 -> 0.72 | J35: =IF(H35="","",H35-F35) | K35: =IF(I35="","",I35-G35) | L35: =IF(OR(H35="",F35=0),"",H35/F35)
A36: 21 | B36: 46142 | C36: Thursday | D36: Phase 2 – Working Day 21 | E36: 4 | F36: ='Norms & Assumptions'!B33*E36 -> 600 | G36: ='Norms & Assumptions'!B35*E36 -> 0.72 | J36: =IF(H36="","",H36-F36) | K36: =IF(I36="","",I36-G36) | L36: =IF(OR(H36="",F36=0),"",H36/F36)
B37: 46143 | C37: Friday | D37: 🏖 Workers' Day | E37: 0 | F37: 0 | G37: 0
B38: 46144 | C38: Saturday | D38: Weekend | E38: 0 | F38: 0 | G38: 0
B39: 46145 | C39: Sunday | D39: Weekend | E39: 0 | F39: 0 | G39: 0
A40: 22 | B40: 46146 | C40: Monday | D40: Phase 2 – Working Day 22 | E40: 4 | F40: ='Norms & Assumptions'!B33*E40 -> 600 | G40: ='Norms & Assumptions'!B35*E40 -> 0.72 | J40: =IF(H40="","",H40-F40) | K40: =IF(I40="","",I40-G40) | L40: =IF(OR(H40="",F40=0),"",H40/F40)
...

Sheet Compartment Targets
A1: COMPARTMENT PRODUCTION TARGETS – PINE CLEAR FELLING
A2: Nkomati Mine, Mpumalanga | Start: 30 Mar 2026 | All targets per SA Forestry Norms
A4: COMPARTMENT | C4: VOLUME & TREE ESTIMATES | G4: PHASE 1 (2 operators) | J4: PHASE 2 (4 operators from 08 Apr)
A5: # | B5: Compartment / Block | C5: Area (ha) | D5: Trees/ha | E5: Est. Trees | F5: Est. Vol (m³) | G5: Ph1 Target Days | H5: Ph1 Target End Date | I5: Ph1 Trees /Op/Day | J5: Ph2 Target Days | K5: Ph2 Target End Date | L5: Ph2 Trees /Op/Day
A6: 1 | B6: A | D6: 800 | E6: =IF(C6="","",C6*D6) | F6: =IF(E6="","",E6*'Norms & Assumptions'!B34) | G6: =IF(E6="","",ROUNDUP(E6/(2*'Norms & Assumptions'!B33),0)) | I6: ='Norms & Assumptions'!B33 -> 150 | J6: =IF(E6="","",ROUNDUP(E6/(4*'Norms & Assumptions'!B33),0)) | L6: ='Norms & Assumptions'!B33 -> 150
A7: 2 | B7: B | D7: 800 | E7: =IF(C7="","",C7*D7) | F7: =IF(E7="","",E7*'Norms & Assumptions'!B34) | G7: =IF(E7="","",ROUNDUP(E7/(2*'Norms & Assumptions'!B33),0)) | I7: ='Norms & Assumptions'!B33 -> 150 | J7: =IF(E7="","",ROUNDUP(E7/(4*'Norms & Assumptions'!B33),0)) | L7: ='Norms & Assumptions'!B33 -> 150
A8: 3 | B8: C | D8: 800 | E8: =IF(C8="","",C8*D8) | F8: =IF(E8="","",E8*'Norms & Assumptions'!B34) | G8: =IF(E8="","",ROUNDUP(E8/(2*'Norms & Assumptions'!B33),0)) | I8: ='Norms & Assumptions'!B33 -> 150 | J8: =IF(E8="","",ROUNDUP(E8/(4*'Norms & Assumptions'!B33),0)) | L8: ='Norms & Assumptions'!B33 -> 150
A9: 4 | B9: D | D9: 800 | E9: =IF(C9="","",C9*D9) | F9: =IF(E9="","",E9*'Norms & Assumptions'!B34) | G9: =IF(E9="","",ROUNDUP(E9/(2*'Norms & Assumptions'!B33),0)) | I9: ='Norms & Assumptions'!B33 -> 150 | J9: =IF(E9="","",ROUNDUP(E9/(4*'Norms & Assumptions'!B33),0)) | L9: ='Norms & Assumptions'!B33 -> 150
A10: 5 | B10: Block 12.68ha | C10: 12.68 | D10: 800 | E10: =IF(C10="","",C10*D10) -> 10144 | F10: =IF(E10="","",E10*'Norms & Assumptions'!B34) -> 3550.4 | G10: =IF(E10="","",ROUNDUP(E10/(2*'Norms & Assumptions'!B33),0)) -> 34 | I10: ='Norms & Assumptions'!B33 -> 150 | J10: =IF(E10="","",ROUNDUP(E10/(4*'Norms & Assumptions'!B33),0)) -> 17 | L10: ='Norms & Assumptions'!B33 -> 150
A11: 6 | B11: Block 3.97ha | C11: 3.97 | D11: 800 | E11: =IF(C11="","",C11*D11) -> 3176 | F11: =IF(E11="","",E11*'Norms & Assumptions'!B34) -> 1111.6 | G11: =IF(E11="","",ROUNDUP(E11/(2*'Norms & Assumptions'!B33),0)) -> 11 | I11: ='Norms & Assumptions'!B33 -> 150 | J11: =IF(E11="","",ROUNDUP(E11/(4*'Norms & Assumptions'!B33),0)) -> 6 | L11: ='Norms & Assumptions'!B33 -> 150
A12: 7 | B12: Block 2.40ha | C12: 2.4 | D12: 800 | E12: =IF(C12="","",C12*D12) -> 1920 | F12: =IF(E12="","",E12*'Norms & Assumptions'!B34) -> 672 | G12: =IF(E12="","",ROUNDUP(E12/(2*'Norms & Assumptions'!B33),0)) -> 7 | I12: ='Norms & Assumptions'!B33 -> 150 | J12: =IF(E12="","",ROUNDUP(E12/(4*'Norms & Assumptions'!B33),0)) -> 4 | L12: ='Norms & Assumptions'!B33 -> 150
A13: 8 | B13: Block 0.863ha | C13: 0.863 | D13: 800 | E13: =IF(C13="","",C13*D13) -> 690.4 | F13: =IF(E13="","",E13*'Norms & Assumptions'!B34) -> 241.64 | G13: =IF(E13="","",ROUNDUP(E13/(2*'Norms & Assumptions'!B33),0)) -> 3 | I13: ='Norms & Assumptions'!B33 -> 150 | J13: =IF(E13="","",ROUNDUP(E13/(4*'Norms & Assumptions'!B33),0)) -> 2 | L13: ='Norms & Assumptions'!B33 -> 150
A14: 9 | B14: Block 2.503ha | C14: 2.503 | D14: 800 | E14: =IF(C14="","",C14*D14) -> 2002.4 | F14: =IF(E14="","",E14*'Norms & Assumptions'!B34) -> 700.84 | G14: =IF(E14="","",ROUNDUP(E14/(2*'Norms & Assumptions'!B33),0)) -> 7 | I14: ='Norms & Assumptions'!B33 -> 150 | J14: =IF(E14="","",ROUNDUP(E14/(4*'Norms & Assumptions'!B33),0)) -> 4 | L14: ='Norms & Assumptions'!B33 -> 150
A15: 10 | B15: Block 0.317ha | C15: 0.317 | D15: 800 | E15: =IF(C15="","",C15*D15) -> 253.6 | F15: =IF(E15="","",E15*'Norms & Assumptions'!B34) -> 88.76 | G15: =IF(E15="","",ROUNDUP(E15/(2*'Norms & Assumptions'!B33),0)) -> 1 | I15: ='Norms & Assumptions'!B33 -> 150 | J15: =IF(E15="","",ROUNDUP(E15/(4*'Norms & Assumptions'!B33),0)) -> 1 | L15: ='Norms & Assumptions'!B33 -> 150
A16: 11 | B16: Block 5ha (est) | C16: 5 | D16: 800 | E16: =IF(C16="","",C16*D16) -> 4000 | F16: =IF(E16="","",E16*'Norms & Assumptions'!B34) -> 1400 | G16: =IF(E16="","",ROUNDUP(E16/(2*'Norms & Assumptions'!B33),0)) -> 14 | I16: ='Norms & Assumptions'!B33 -> 150 | J16: =IF(E16="","",ROUNDUP(E16/(4*'Norms & Assumptions'!B33),0)) -> 7 | L16: ='Norms & Assumptions'!B33 -> 150
A17: 12 | B17: 42.9ha – Outside fence | C17: 42.9 | D17: 800 | E17: =IF(C17="","",C17*D17) -> 34320 | F17: =IF(E17="","",E17*'Norms & Assumptions'!B34) -> 12012 | G17: =IF(E17="","",ROUNDUP(E17/(2*'Norms & Assumptions'!B33),0)) -> 115 | I17: ='Norms & Assumptions'!B33 -> 150 | J17: =IF(E17="","",ROUNDUP(E17/(4*'Norms & Assumptions'!B33),0)) -> 58 | L17: ='Norms & Assumptions'!B33 -> 150
A18: 13 | B18: 14.9ha – Outside fence | C18: 14.9 | D18: 800 | E18: =IF(C18="","",C18*D18) -> 11920 | F18: =IF(E18="","",E18*'Norms & Assumptions'!B34) -> 4172 | G18: =IF(E18="","",ROUNDUP(E18/(2*'Norms & Assumptions'!B33),0)) -> 40 | I18: ='Norms & Assumptions'!B33 -> 150 | J18: =IF(E18="","",ROUNDUP(E18/(4*'Norms & Assumptions'!B33),0)) -> 20 | L18: ='Norms & Assumptions'!B33 -> 150
A19: TOTALS | C19: =SUMIF(C6:C18,">0") -> 85.533 | E19: =SUMIF(E6:E18,">0") -> 68426.4 | F19: =SUMIF(F6:F18,">0") -> 23949.24
A21: ⚠ Compartments A, B, C, D: Enter exact hectares in blue cells (Col C). Trees/ha (Col D) can be adjusted per stand inventory. Phase 1 = 2 operators (30 Mar–07 Apr) | Phase 2 = 4 operators (08 Apr+)

Sheet Operator Daily Log
A1: OPERATOR DAILY LOG – INDIVIDUAL PERFORMANCE TRACKER
A2: One row per operator per day | Blue cells = enter actual values
A4: # | B4: Date | C4: Operator Name | D4: Compartment | E4: Chainsaw Serial # | F4: Target Trees/Day | G4: Actual Trees | H4: Target m³/Day | I4: Actual m³ | J4: Tree Var | K4: m³ Var | L4: Achievement % | M4: Notes / Issues
A5: 1 | F5: ='Norms & Assumptions'!B33 -> 150 | H5: ='Norms & Assumptions'!B35 -> 0.18 | J5: =IF(G5="","",G5-F5) | K5: =IF(I5="","",I5-H5) | L5: =IF(OR(G5="",F5=0),"",G5/F5)
A6: 2 | F6: ='Norms & Assumptions'!B33 -> 150 | H6: ='Norms & Assumptions'!B35 -> 0.18 | J6: =IF(G6="","",G6-F6) | K6: =IF(I6="","",I6-H6) | L6: =IF(OR(G6="",F6=0),"",G6/F6)
A7: 3 | F7: ='Norms & Assumptions'!B33 -> 150 | H7: ='Norms & Assumptions'!B35 -> 0.18 | J7: =IF(G7="","",G7-F7) | K7: =IF(I7="","",I7-H7) | L7: =IF(OR(G7="",F7=0),"",G7/F7)
A8: 4 | F8: ='Norms & Assumptions'!B33 -> 150 | H8: ='Norms & Assumptions'!B35 -> 0.18 | J8: =IF(G8="","",G8-F8) | K8: =IF(I8="","",I8-H8) | L8: =IF(OR(G8="",F8=0),"",G8/F8)
A9: 5 | F9: ='Norms & Assumptions'!B33 -> 150 | H9: ='Norms & Assumptions'!B35 -> 0.18 | J9: =IF(G9="","",G9-F9) | K9: =IF(I9="","",I9-H9) | L9: =IF(OR(G9="",F9=0),"",G9/F9)
A10: 6 | F10: ='Norms & Assumptions'!B33 -> 150 | H10: ='Norms & Assumptions'!B35 -> 0.18 | J10: =IF(G10="","",G10-F10) | K10: =IF(I10="","",I10-H10) | L10: =IF(OR(G10="",F10=0),"",G10/F10)
A11: 7 | F11: ='Norms & Assumptions'!B33 -> 150 | H11: ='Norms & Assumptions'!B35 -> 0.18 | J11: =IF(G11="","",G11-F11) | K11: =IF(I11="","",I11-H11) | L11: =IF(OR(G11="",F11=0),"",G11/F11)
A12: 8 | F12: ='Norms & Assumptions'!B33 -> 150 | H12: ='Norms & Assumptions'!B35 -> 0.18 | J12: =IF(G12="","",G12-F12) | K12: =IF(I12="","",I12-H12) | L12: =IF(OR(G12="",F12=0),"",G12/F12)
A13: 9 | F13: ='Norms & Assumptions'!B33 -> 150 | H13: ='Norms & Assumptions'!B35 -> 0.18 | J13: =IF(G13="","",G13-F13) | K13: =IF(I13="","",I13-H13) | L13: =IF(OR(G13="",F13=0),"",G13/F13)
A14: 10 | F14: ='Norms & Assumptions'!B33 -> 150 | H14: ='Norms & Assumptions'!B35 -> 0.18 | J14: =IF(G14="","",G14-F14) | K14: =IF(I14="","",I14-H14) | L14: =IF(OR(G14="",F14=0),"",G14/F14)
A15: 11 | F15: ='Norms & Assumptions'!B33 -> 150 | H15: ='Norms & Assumptions'!B35 -> 0.18 | J15: =IF(G15="","",G15-F15) | K15: =IF(I15="","",I15-H15) | L15: =IF(OR(G15="",F15=0),"",G15/F15)
A16: 12 | F16: ='Norms & Assumptions'!B33 -> 150 | H16: ='Norms & Assumptions'!B35 -> 0.18 | J16: =IF(G16="","",G16-F16) | K16: =IF(I16="","",I16-H16) | L16: =IF(OR(G16="",F16=0),"",G16/F16)
A17: 13 | F17: ='Norms & Assumptions'!B33 -> 150 | H17: ='Norms & Assumptions'!B35 -> 0.18 | J17: =IF(G17="","",G17-F17) | K17: =IF(I17="","",I17-H17) | L17: =IF(OR(G17="",F17=0),"",G17/F17)
A18: 14 | F18: ='Norms & Assumptions'!B33 -> 150 | H18: ='Norms & Assumptions'!B35 -> 0.18 | J18: =IF(G18="","",G18-F18) | K18: =IF(I18="","",I18-H18) | L18: =IF(OR(G18="",F18=0),"",G18/F18)
A19: 15 | F19: ='Norms & Assumptions'!B33 -> 150 | H19: ='Norms & Assumptions'!B35 -> 0.18 | J19: =IF(G19="","",G19-F19) | K19: =IF(I19="","",I19-H19) | L19: =IF(OR(G19="",F19=0),"",G19/F19)
A20: 16 | F20: ='Norms & Assumptions'!B33 -> 150 | H20: ='Norms & Assumptions'!B35 -> 0.18 | J20: =IF(G20="","",G20-F20) | K20: =IF(I20="","",I20-H20) | L20: =IF(OR(G20="",F20=0),"",G20/F20)
A21: 17 | F21: ='Norms & Assumptions'!B33 -> 150 | H21: ='Norms & Assumptions'!B35 -> 0.18 | J21: =IF(G21="","",G21-F21) | K21: =IF(I21="","",I21-H21) | L21: =IF(OR(G21="",F21=0),"",G21/F21)
A22: 18 | F22: ='Norms & Assumptions'!B33 -> 150 | H22: ='Norms & Assumptions'!B35 -> 0.18 | J22: =IF(G22="","",G22-F22) | K22: =IF(I22="","",I22-H22) | L22: =IF(OR(G22="",F22=0),"",G22/F22)
A23: 19 | F23: ='Norms & Assumptions'!B33 -> 150 | H23: ='Norms & Assumptions'!B35 -> 0.18 | J23: =IF(G23="","",G23-F23) | K23: =IF(I23="","",I23-H23) | L23: =IF(OR(G23="",F23=0),"",G23/F23)
A24: 20 | F24: ='Norms & Assumptions'!B33 -> 150 | H24: ='Norms & Assumptions'!B35 -> 0.18 | J24: =IF(G24="","",G24-F24) | K24: =IF(I24="","",I24-H24) | L24: =IF(OR(G24="",F24=0),"",G24/F24)
A25: 21 | F25: ='Norms & Assumptions'!B33 -> 150 | H25: ='Norms & Assumptions'!B35 -> 0.18 | J25: =IF(G25="","",G25-F25) | K25: =IF(I25="","",I25-H25) | L25: =IF(OR(G25="",F25=0),"",G25/F25)
A26: 22 | F26: ='Norms & Assumptions'!B33 -> 150 | H26: ='Norms & Assumptions'!B35 -> 0.18 | J26: =IF(G26="","",G26-F26) | K26: =IF(I26="","",I26-H26) | L26: =IF(OR(G26="",F26=0),"",G26/F26)
A27: 23 | F27: ='Norms & Assumptions'!B33 -> 150 | H27: ='Norms & Assumptions'!B35 -> 0.18 | J27: =IF(G27="","",G27-F27) | K27: =IF(I27="","",I27-H27) | L27: =IF(OR(G27="",F27=0),"",G27/F27)
A28: 24 | F28: ='Norms & Assumptions'!B33 -> 150 | H28: ='Norms & Assumptions'!B35 -> 0.18 | J28: =IF(G28="","",G28-F28) | K28: =IF(I28="","",I28-H28) | L28: =IF(OR(G28="",F28=0),"",G28/F28)
A29: 25 | F29: ='Norms & Assumptions'!B33 -> 150 | H29: ='Norms & Assumptions'!B35 -> 0.18 | J29: =IF(G29="","",G29-F29) | K29: =IF(I29="","",I29-H29) | L29: =IF(OR(G29="",F29=0),"",G29/F29)
A30: 26 | F30: ='Norms & Assumptions'!B33 -> 150 | H30: ='Norms & Assumptions'!B35 -> 0.18 | J30: =IF(G30="","",G30-F30) | K30: =IF(I30="","",I30-H30) | L30: =IF(OR(G30="",F30=0),"",G30/F30)
A31: 27 | F31: ='Norms & Assumptions'!B33 -> 150 | H31: ='Norms & Assumptions'!B35 -> 0.18 | J31: =IF(G31="","",G31-F31) | K31: =IF(I31="","",I31-H31) | L31: =IF(OR(G31="",F31=0),"",G31/F31)
A32: 28 | F32: ='Norms & Assumptions'!B33 -> 150 | H32: ='Norms & Assumptions'!B35 -> 0.18 | J32: =IF(G32="","",G32-F32) | K32: =IF(I32="","",I32-H32) | L32: =IF(OR(G32="",F32=0),"",G32/F32)
A33: 29 | F33: ='Norms & Assumptions'!B33 -> 150 | H33: ='Norms & Assumptions'!B35 -> 0.18 | J33: =IF(G33="","",G33-F33) | K33: =IF(I33="","",I33-H33) | L33: =IF(OR(G33="",F33=0),"",G33/F33)
A34: 30 | F34: ='Norms & Assumptions'!B33 -> 150 | H34: ='Norms & Assumptions'!B35 -> 0.18 | J34: =IF(G34="","",G34-F34) | K34: =IF(I34="","",I34-H34) | L34: =IF(OR(G34="",F34=0),"",G34/F34)
A35: 31 | F35: ='Norms & Assumptions'!B33 -> 150 | H35: ='Norms & Assumptions'!B35 -> 0.18 | J35: =IF(G35="","",G35-F35) | K35: =IF(I35="","",I35-H35) | L35: =IF(OR(G35="",F35=0),"",G35/F35)
A36: 32 | F36: ='Norms & Assumptions'!B33 -> 150 | H36: ='Norms & Assumptions'!B35 -> 0.18 | J36: =IF(G36="","",G36-F36) | K36: =IF(I36="","",I36-H36) | L36: =IF(OR(G36="",F36=0),"",G36/F36)
A37: 33 | F37: ='Norms & Assumptions'!B33 -> 150 | H37: ='Norms & Assumptions'!B35 -> 0.18 | J37: =IF(G37="","",G37-F37) | K37: =IF(I37="","",I37-H37) | L37: =IF(OR(G37="",F37=0),"",G37/F37)
A38: 34 | F38: ='Norms & Assumptions'!B33 -> 150 | H38: ='Norms & Assumptions'!B35 -> 0.18 | J38: =IF(G38="","",G38-F38) | K38: =IF(I38="","",I38-H38) | L38: =IF(OR(G38="",F38=0),"",G38/F38)
A39: 35 | F39: ='Norms & Assumptions'!B33 -> 150 | H39: ='Norms & Assumptions'!B35 -> 0.18 | J39: =IF(G39="","",G39-F39) | K39: =IF(I39="","",I39-H39) | L39: =IF(OR(G39="",F39=0),"",G39/F39)
A40: 36 | F40: ='Norms & Assumptions'!B33 -> 150 | H40: ='Norms & Assumptions'!B35 -> 0.18 | J40: =IF(G40="","",G40-F40) | K40: =IF(I40="","",I40-H40) | L40: =IF(OR(G40="",F40=0),"",G40/F40)
A41: 37 | F41: ='Norms & Assumptions'!B33 -> 150 | H41: ='Norms & Assumptions'!B35 -> 0.18 | J41: =IF(G41="","",G41-F41) | K41: =IF(I41="","",I41-H41) | L41: =IF(OR(G41="",F41=0),"",G41/F41)
...

Sheet Consumables Tracker
A1: CONSUMABLES DAILY TRACKER – ACTUAL vs TARGET USAGE
A2: Operators working auto-adjusts: 2 ops before 08 Apr | 4 ops from 08 Apr onwards
A4: # | B4: Date | C4: Consumable Item | D4: Unit | E4: Target/Op/Day | F4: Operators Working | G4: Total Target /Day | H4: Actual Issued | I4: Variance | J4: Notes
A5: 1 | C5: Fuel mix (2-stroke 50:1) | D5: litres | E5: ='Norms & Assumptions'!B43 -> 2.5 | F5: =IF(B5="",2,IF(B5>=DATE(2026,4,8),4,2)) -> 2 | G5: =E5*F5 -> 5 | I5: =IF(H5="","",H5-G5)
A6: 2 | B6: =B5 -> 0 | C6: Bar & chain oil | D6: litres | E6: ='Norms & Assumptions'!B44 -> 1.2 | F6: =IF(B5="",2,IF(B5>=DATE(2026,4,8),4,2)) -> 2 | G6: =E6*F6 -> 2.4 | I6: =IF(H6="","",H6-G6)
A7: 3 | B7: =B5 -> 0 | C7: Saw chains | D7: chains | E7: ='Norms & Assumptions'!B45 -> 0.5 | F7: =IF(B5="",2,IF(B5>=DATE(2026,4,8),4,2)) -> 2 | G7: =E7*F7 -> 1 | I7: =IF(H7="","",H7-G7)
A8: 4 | B8: =B5 -> 0 | C8: Guide bar | D8: bars | E8: ='Norms & Assumptions'!B46 -> 0.05 | F8: =IF(B5="",2,IF(B5>=DATE(2026,4,8),4,2)) -> 2 | G8: =E8*F8 -> 0.1 | I8: =IF(H8="","",H8-G8)
A9: 5 | B9: =B5 -> 0 | C9: Gloves (pairs) | D9: pairs | E9: ='Norms & Assumptions'!B47 -> 0.2 | F9: =IF(B5="",2,IF(B5>=DATE(2026,4,8),4,2)) -> 2 | G9: =E9*F9 -> 0.4 | I9: =IF(H9="","",H9-G9)
A10: 6 | B10: =B5 -> 0 | C10: Round file (4mm) | D10: files | E10: ='Norms & Assumptions'!B48 -> 0.2 | F10: =IF(B5="",2,IF(B5>=DATE(2026,4,8),4,2)) -> 2 | G10: =E10*F10 -> 0.4 | I10: =IF(H10="","",H10-G10)
A11: 7 | B11: =B5 -> 0 | C11: Spark plug | D11: plugs | E11: ='Norms & Assumptions'!B49 -> 0.05 | F11: =IF(B5="",2,IF(B5>=DATE(2026,4,8),4,2)) -> 2 | G11: =E11*F11 -> 0.1 | I11: =IF(H11="","",H11-G11)
A12: 8 | B12: =B5 -> 0 | C12: Air filter | D12: filters | E12: ='Norms & Assumptions'!B50 -> 0.033 | F12: =IF(B5="",2,IF(B5>=DATE(2026,4,8),4,2)) -> 2 | G12: =E12*F12 -> 0.066 | I12: =IF(H12="","",H12-G12)
A13: 9 | C13: Fuel mix (2-stroke 50:1) | D13: litres | E13: ='Norms & Assumptions'!B43 -> 2.5 | F13: =IF(B13="",2,IF(B13>=DATE(2026,4,8),4,2)) -> 2 | G13: =E13*F13 -> 5 | I13: =IF(H13="","",H13-G13)
A14: 10 | B14: =B13 -> 0 | C14: Bar & chain oil | D14: litres | E14: ='Norms & Assumptions'!B44 -> 1.2 | F14: =IF(B13="",2,IF(B13>=DATE(2026,4,8),4,2)) -> 2 | G14: =E14*F14 -> 2.4 | I14: =IF(H14="","",H14-G14)
A15: 11 | B15: =B13 -> 0 | C15: Saw chains | D15: chains | E15: ='Norms & Assumptions'!B45 -> 0.5 | F15: =IF(B13="",2,IF(B13>=DATE(2026,4,8),4,2)) -> 2 | G15: =E15*F15 -> 1 | I15: =IF(H15="","",H15-G15)
A16: 12 | B16: =B13 -> 0 | C16: Guide bar | D16: bars | E16: ='Norms & Assumptions'!B46 -> 0.05 | F16: =IF(B13="",2,IF(B13>=DATE(2026,4,8),4,2)) -> 2 | G16: =E16*F16 -> 0.1 | I16: =IF(H16="","",H16-G16)
A17: 13 | B17: =B13 -> 0 | C17: Gloves (pairs) | D17: pairs | E17: ='Norms & Assumptions'!B47 -> 0.2 | F17: =IF(B13="",2,IF(B13>=DATE(2026,4,8),4,2)) -> 2 | G17: =E17*F17 -> 0.4 | I17: =IF(H17="","",H17-G17)
A18: 14 | B18: =B13 -> 0 | C18: Round file (4mm) | D18: files | E18: ='Norms & Assumptions'!B48 -> 0.2 | F18: =IF(B13="",2,IF(B13>=DATE(2026,4,8),4,2)) -> 2 | G18: =E18*F18 -> 0.4 | I18: =IF(H18="","",H18-G18)
A19: 15 | B19: =B13 -> 0 | C19: Spark plug | D19: plugs | E19: ='Norms & Assumptions'!B49 -> 0.05 | F19: =IF(B13="",2,IF(B13>=DATE(2026,4,8),4,2)) -> 2 | G19: =E19*F19 -> 0.1 | I19: =IF(H19="","",H19-G19)
A20: 16 | B20: =B13 -> 0 | C20: Air filter | D20: filters | E20: ='Norms & Assumptions'!B50 -> 0.033 | F20: =IF(B13="",2,IF(B13>=DATE(2026,4,8),4,2)) -> 2 | G20: =E20*F20 -> 0.066 | I20: =IF(H20="","",H20-G20)
A21: 17 | C21: Fuel mix (2-stroke 50:1) | D21: litres | E21: ='Norms & Assumptions'!B43 -> 2.5 | F21: =IF(B21="",2,IF(B21>=DATE(2026,4,8),4,2)) -> 2 | G21: =E21*F21 -> 5 | I21: =IF(H21="","",H21-G21)
A22: 18 | B22: =B21 -> 0 | C22: Bar & chain oil | D22: litres | E22: ='Norms & Assumptions'!B44 -> 1.2 | F22: =IF(B21="",2,IF(B21>=DATE(2026,4,8),4,2)) -> 2 | G22: =E22*F22 -> 2.4 | I22: =IF(H22="","",H22-G22)
A23: 19 | B23: =B21 -> 0 | C23: Saw chains | D23: chains | E23: ='Norms & Assumptions'!B45 -> 0.5 | F23: =IF(B21="",2,IF(B21>=DATE(2026,4,8),4,2)) -> 2 | G23: =E23*F23 -> 1 | I23: =IF(H23="","",H23-G23)
A24: 20 | B24: =B21 -> 0 | C24: Guide bar | D24: bars | E24: ='Norms & Assumptions'!B46 -> 0.05 | F24: =IF(B21="",2,IF(B21>=DATE(2026,4,8),4,2)) -> 2 | G24: =E24*F24 -> 0.1 | I24: =IF(H24="","",H24-G24)
A25: 21 | B25: =B21 -> 0 | C25: Gloves (pairs) | D25: pairs | E25: ='Norms & Assumptions'!B47 -> 0.2 | F25: =IF(B21="",2,IF(B21>=DATE(2026,4,8),4,2)) -> 2 | G25: =E25*F25 -> 0.4 | I25: =IF(H25="","",H25-G25)
A26: 22 | B26: =B21 -> 0 | C26: Round file (4mm) | D26: files | E26: ='Norms & Assumptions'!B48 -> 0.2 | F26: =IF(B21="",2,IF(B21>=DATE(2026,4,8),4,2)) -> 2 | G26: =E26*F26 -> 0.4 | I26: =IF(H26="","",H26-G26)
A27: 23 | B27: =B21 -> 0 | C27: Spark plug | D27: plugs | E27: ='Norms & Assumptions'!B49 -> 0.05 | F27: =IF(B21="",2,IF(B21>=DATE(2026,4,8),4,2)) -> 2 | G27: =E27*F27 -> 0.1 | I27: =IF(H27="","",H27-G27)
A28: 24 | B28: =B21 -> 0 | C28: Air filter | D28: filters | E28: ='Norms & Assumptions'!B50 -> 0.033 | F28: =IF(B21="",2,IF(B21>=DATE(2026,4,8),4,2)) -> 2 | G28: =E28*F28 -> 0.066 | I28: =IF(H28="","",H28-G28)
A29: 25 | C29: Fuel mix (2-stroke 50:1) | D29: litres | E29: ='Norms & Assumptions'!B43 -> 2.5 | F29: =IF(B29="",2,IF(B29>=DATE(2026,4,8),4,2)) -> 2 | G29: =E29*F29 -> 5 | I29: =IF(H29="","",H29-G29)
A30: 26 | B30: =B29 -> 0 | C30: Bar & chain oil | D30: litres | E30: ='Norms & Assumptions'!B44 -> 1.2 | F30: =IF(B29="",2,IF(B29>=DATE(2026,4,8),4,2)) -> 2 | G30: =E30*F30 -> 2.4 | I30: =IF(H30="","",H30-G30)
A31: 27 | B31: =B29 -> 0 | C31: Saw chains | D31: chains | E31: ='Norms & Assumptions'!B45 -> 0.5 | F31: =IF(B29="",2,IF(B29>=DATE(2026,4,8),4,2)) -> 2 | G31: =E31*F31 -> 1 | I31: =IF(H31="","",H31-G31)
A32: 28 | B32: =B29 -> 0 | C32: Guide bar | D32: bars | E32: ='Norms & Assumptions'!B46 -> 0.05 | F32: =IF(B29="",2,IF(B29>=DATE(2026,4,8),4,2)) -> 2 | G32: =E32*F32 -> 0.1 | I32: =IF(H32="","",H32-G32)
A33: 29 | B33: =B29 -> 0 | C33: Gloves (pairs) | D33: pairs | E33: ='Norms & Assumptions'!B47 -> 0.2 | F33: =IF(B29="",2,IF(B29>=DATE(2026,4,8),4,2)) -> 2 | G33: =E33*F33 -> 0.4 | I33: =IF(H33="","",H33-G33)
A34: 30 | B34: =B29 -> 0 | C34: Round file (4mm) | D34: files | E34: ='Norms & Assumptions'!B48 -> 0.2 | F34: =IF(B29="",2,IF(B29>=DATE(2026,4,8),4,2)) -> 2 | G34: =E34*F34 -> 0.4 | I34: =IF(H34="","",H34-G34)
A35: 31 | B35: =B29 -> 0 | C35: Spark plug | D35: plugs | E35: ='Norms & Assumptions'!B49 -> 0.05 | F35: =IF(B29="",2,IF(B29>=DATE(2026,4,8),4,2)) -> 2 | G35: =E35*F35 -> 0.1 | I35: =IF(H35="","",H35-G35)
A36: 32 | B36: =B29 -> 0 | C36: Air filter | D36: filters | E36: ='Norms & Assumptions'!B50 -> 0.033 | F36: =IF(B29="",2,IF(B29>=DATE(2026,4,8),4,2)) -> 2 | G36: =E36*F36 -> 0.066 | I36: =IF(H36="","",H36-G36)
A37: 33 | C37: Fuel mix (2-stroke 50:1) | D37: litres | E37: ='Norms & Assumptions'!B43 -> 2.5 | F37: =IF(B37="",2,IF(B37>=DATE(2026,4,8),4,2)) -> 2 | G37: =E37*F37 -> 5 | I37: =IF(H37="","",H37-G37)
A38: 34 | B38: =B37 -> 0 | C38: Bar & chain oil | D38: litres | E38: ='Norms & Assumptions'!B44 -> 1.2 | F38: =IF(B37="",2,IF(B37>=DATE(2026,4,8),4,2)) -> 2 | G38: =E38*F38 -> 2.4 | I38: =IF(H38="","",H38-G38)
A39: 35 | B39: =B37 -> 0 | C39: Saw chains | D39: chains | E39: ='Norms & Assumptions'!B45 -> 0.5 | F39: =IF(B37="",2,IF(B37>=DATE(2026,4,8),4,2)) -> 2 | G39: =E39*F39 -> 1 | I39: =IF(H39="","",H39-G39)
A40: 36 | B40: =B37 -> 0 | C40: Guide bar | D40: bars | E40: ='Norms & Assumptions'!B46 -> 0.05 | F40: =IF(B37="",2,IF(B37>=DATE(2026,4,8),4,2)) -> 2 | G40: =E40*F40 -> 0.1 | I40: =IF(H40="","",H40-G40)
A41: 37 | B41: =B37 -> 0 | C41: Gloves (pairs) | D41: pairs | E41: ='Norms & Assumptions'!B47 -> 0.2 | F41: =IF(B37="",2,IF(B37>=DATE(2026,4,8),4,2)) -> 2 | G41: =E41*F41 -> 0.4 | I41: =IF(H41="","",H41-G41)
...

Sheet Performance Dashboard
A1: PERFORMANCE DASHBOARD – PROJECT SUMMARY
A2: Auto-calculated from Project Schedule & Operator Log | Start: 30 Mar 2026
A4: PROJECT INFORMATION
A5: Project Start Date | B5: 30 March 2026
A6: Phase 1 (2 operators) | B6: 30 Mar – 07 Apr 2026 | C6: Mon–Fri 07:00–15:30
A7: Phase 2 (4 operators) | B7: 08 Apr 2026 onwards | C7: Mon–Fri 07:00–15:30
A8: Shift Hours | B8: 07:00 – 15:30 | C8: 8.5 hrs gross | 6.5 hrs effective cutting
A9: Equipment | B9: Stihl MS 382 | C9: One saw per operator (SA OHS)
A10: SA Holidays in project | B10: 10 | C10: Days with zero production
A12: PRODUCTION KPIs (from Project Schedule)
A13: KPI | B13: Target | C13: Actual | D13: Variance | E13: Status
A14: Total Trees – Target (Project) | B14: =SUMIF('Project Schedule'!E5:E220,">0",'Project Schedule'!F5:F220) -> 87900 | C14: =SUM('Project Schedule'!H5:H220) -> 0 | D14: =C14-B14 -> -87900 | E14: =IF(C14>=B14,"✅ ON TARGET","⚠ BELOW TARGET") -> ⚠ BELOW TARGET
A15: Total Volume m³ – Target | B15: =SUMIF('Project Schedule'!E5:E220,">0",'Project Schedule'!G5:G220) -> 105.48 | C15: =SUM('Project Schedule'!I5:I220) -> 0 | D15: =C15-B15 -> -105.48 | E15: =IF(C15>=B15,"✅ ON TARGET","⚠ BELOW TARGET") -> ⚠ BELOW TARGET
A16: Overall Achievement % | B16: 100% | C16: =IFERROR(SUM('Project Schedule'!H5:H220)/SUMIF('Project Schedule'!E5:E220,">0",'Project Schedule'!F5:F220),0) -> 0 | D16: =C16-B16 -> -1 | E16: =IF(C16>=B16,"✅ ON TARGET","⚠ BELOW TARGET") -> ⚠ BELOW TARGET
A17: Working Days – Phase 1 (2 ops) | B17: 5 | C17: → Enter actuals | D17: — | E17: —
A18: Working Days – Phase 2 (4 ops) | B18: See Project Schedule | C18: → Enter actuals | D18: — | E18: —
A19: Phase 1 Cumulative Target Trees | B19: 1500 | C19: → Enter actuals | D19: — | E19: —
A20: Phase 1 Cumulative Target m³ | B20: 525.0 | C20: → Enter actuals | D20: — | E20: —
A23: PHASE PRODUCTION SUMMARY
A24: Phase | B24: Period | C24: Operators | D24: Working Days | E24: Trees Target
A25: Phase 1 | B25: 30 Mar – 07 Apr 2026 | C25: 2 | D25: 5 | E25: 1500
A26: Phase 2 | B26: 08 Apr 2026 onwards | C26: 4 | D26: See Schedule | E26: Per schedule
A28: HOW TO USE THIS WORKBOOK
A29: 1. NORMS & ASSUMPTIONS: Review SA norms, SA holiday list, and project schedule dates.
A30: 2. PROJECT SCHEDULE: This is your master calendar. Enter actual trees felled & m³ per working day (blue cells).
A31: 3. COMPARTMENT TARGETS: Enter exact hectares for blocks A–D. Adjust trees/ha per stand inventory.
A32: 4. OPERATOR DAILY LOG: Log individual operator performance (one row per person per day).
A33: 5. CONSUMABLES TRACKER: Enter daily consumables issued. Operators auto-adjust by date phase.
A34: 6. PERFORMANCE DASHBOARD: Summarises everything – review weekly for corrective actions.
